Traceback (most recent call last):
  File "C:\Anaconda\lib\site-packages\jupyter_cache\executors\utils.py", line 58, in single_nb_execution
    executenb(
  File "C:\Anaconda\lib\site-packages\nbclient\client.py", line 1204, in execute
    return NotebookClient(nb=nb, resources=resources, km=km, **kwargs).execute()
  File "C:\Anaconda\lib\site-packages\nbclient\util.py", line 84, in wrapped
    return just_run(coro(*args, **kwargs))
  File "C:\Anaconda\lib\site-packages\nbclient\util.py", line 62, in just_run
    return loop.run_until_complete(coro)
  File "C:\Anaconda\lib\asyncio\base_events.py", line 647, in run_until_complete
    return future.result()
  File "C:\Anaconda\lib\site-packages\nbclient\client.py", line 663, in async_execute
    await self.async_execute_cell(
  File "C:\Anaconda\lib\site-packages\nbclient\client.py", line 965, in async_execute_cell
    await self._check_raise_for_error(cell, cell_index, exec_reply)
  File "C:\Anaconda\lib\site-packages\nbclient\client.py", line 862, in _check_raise_for_error
    raise CellExecutionError.from_cell_and_msg(cell, exec_reply_content)
nbclient.exceptions.CellExecutionError: An error occurred while executing the following cell:
------------------
for i in range(10):
    try:
        values = np.random.choice( original, size=5, replace=False)
    except:
        values = np.random.choice( original, size=4, replace=False)
    original = list(set(original).difference(values))
    results.append( values )
------------------

[1;31m---------------------------------------------------------------------------[0m
[1;31mValueError[0m                                Traceback (most recent call last)
[1;32m~\AppData\Local\Temp\ipykernel_1128\3874061475.py[0m in [0;36m<module>[1;34m[0m
[0;32m      2[0m     [1;32mtry[0m[1;33m:[0m[1;33m[0m[1;33m[0m[0m
[1;32m----> 3[1;33m         [0mvalues[0m [1;33m=[0m [0mnp[0m[1;33m.[0m[0mrandom[0m[1;33m.[0m[0mchoice[0m[1;33m([0m [0moriginal[0m[1;33m,[0m [0msize[0m[1;33m=[0m[1;36m5[0m[1;33m,[0m [0mreplace[0m[1;33m=[0m[1;32mFalse[0m[1;33m)[0m[1;33m[0m[1;33m[0m[0m
[0m[0;32m      4[0m     [1;32mexcept[0m[1;33m:[0m[1;33m[0m[1;33m[0m[0m

[1;32mmtrand.pyx[0m in [0;36mnumpy.random.mtrand.RandomState.choice[1;34m()[0m

[1;31mValueError[0m: 'a' cannot be empty unless no samples are taken

During handling of the above exception, another exception occurred:

[1;31mValueError[0m                                Traceback (most recent call last)
[1;32m~\AppData\Local\Temp\ipykernel_1128\3874061475.py[0m in [0;36m<module>[1;34m[0m
[0;32m      3[0m         [0mvalues[0m [1;33m=[0m [0mnp[0m[1;33m.[0m[0mrandom[0m[1;33m.[0m[0mchoice[0m[1;33m([0m [0moriginal[0m[1;33m,[0m [0msize[0m[1;33m=[0m[1;36m5[0m[1;33m,[0m [0mreplace[0m[1;33m=[0m[1;32mFalse[0m[1;33m)[0m[1;33m[0m[1;33m[0m[0m
[0;32m      4[0m     [1;32mexcept[0m[1;33m:[0m[1;33m[0m[1;33m[0m[0m
[1;32m----> 5[1;33m         [0mvalues[0m [1;33m=[0m [0mnp[0m[1;33m.[0m[0mrandom[0m[1;33m.[0m[0mchoice[0m[1;33m([0m [0moriginal[0m[1;33m,[0m [0msize[0m[1;33m=[0m[1;36m4[0m[1;33m,[0m [0mreplace[0m[1;33m=[0m[1;32mFalse[0m[1;33m)[0m[1;33m[0m[1;33m[0m[0m
[0m[0;32m      6[0m     [0moriginal[0m [1;33m=[0m [0mlist[0m[1;33m([0m[0mset[0m[1;33m([0m[0moriginal[0m[1;33m)[0m[1;33m.[0m[0mdifference[0m[1;33m([0m[0mvalues[0m[1;33m)[0m[1;33m)[0m[1;33m[0m[1;33m[0m[0m
[0;32m      7[0m     [0mresults[0m[1;33m.[0m[0mappend[0m[1;33m([0m [0mvalues[0m [1;33m)[0m[1;33m[0m[1;33m[0m[0m

[1;32mmtrand.pyx[0m in [0;36mnumpy.random.mtrand.RandomState.choice[1;34m()[0m

[1;31mValueError[0m: 'a' cannot be empty unless no samples are taken
ValueError: 'a' cannot be empty unless no samples are taken

