Traceback (most recent call last):
  File "C:\Anaconda\lib\site-packages\jupyter_cache\executors\utils.py", line 58, in single_nb_execution
    executenb(
  File "C:\Anaconda\lib\site-packages\nbclient\client.py", line 1204, in execute
    return NotebookClient(nb=nb, resources=resources, km=km, **kwargs).execute()
  File "C:\Anaconda\lib\site-packages\nbclient\util.py", line 84, in wrapped
    return just_run(coro(*args, **kwargs))
  File "C:\Anaconda\lib\site-packages\nbclient\util.py", line 62, in just_run
    return loop.run_until_complete(coro)
  File "C:\Anaconda\lib\asyncio\base_events.py", line 647, in run_until_complete
    return future.result()
  File "C:\Anaconda\lib\site-packages\nbclient\client.py", line 663, in async_execute
    await self.async_execute_cell(
  File "C:\Anaconda\lib\site-packages\nbclient\client.py", line 965, in async_execute_cell
    await self._check_raise_for_error(cell, cell_index, exec_reply)
  File "C:\Anaconda\lib\site-packages\nbclient\client.py", line 862, in _check_raise_for_error
    raise CellExecutionError.from_cell_and_msg(cell, exec_reply_content)
nbclient.exceptions.CellExecutionError: An error occurred while executing the following cell:
------------------
folder = "group_3"
relative_path = "..\..\_output\sbs\municipal/" + folder

if not os.path.exists(relative_path):
    os.makedirs(relative_path)
------------------

[1;31m---------------------------------------------------------------------------[0m
[1;31mPermissionError[0m                           Traceback (most recent call last)
[1;32m~\AppData\Local\Temp\ipykernel_3360\4092705968.py[0m in [0;36m<module>[1;34m[0m
[0;32m      3[0m [1;33m[0m[0m
[0;32m      4[0m [1;32mif[0m [1;32mnot[0m [0mos[0m[1;33m.[0m[0mpath[0m[1;33m.[0m[0mexists[0m[1;33m([0m[0mrelative_path[0m[1;33m)[0m[1;33m:[0m[1;33m[0m[1;33m[0m[0m
[1;32m----> 5[1;33m     [0mos[0m[1;33m.[0m[0mmakedirs[0m[1;33m([0m[0mrelative_path[0m[1;33m)[0m[1;33m[0m[1;33m[0m[0m
[0m
[1;32mC:\Anaconda\lib\os.py[0m in [0;36mmakedirs[1;34m(name, mode, exist_ok)[0m
[0;32m    213[0m     [1;32mif[0m [0mhead[0m [1;32mand[0m [0mtail[0m [1;32mand[0m [1;32mnot[0m [0mpath[0m[1;33m.[0m[0mexists[0m[1;33m([0m[0mhead[0m[1;33m)[0m[1;33m:[0m[1;33m[0m[1;33m[0m[0m
[0;32m    214[0m         [1;32mtry[0m[1;33m:[0m[1;33m[0m[1;33m[0m[0m
[1;32m--> 215[1;33m             [0mmakedirs[0m[1;33m([0m[0mhead[0m[1;33m,[0m [0mexist_ok[0m[1;33m=[0m[0mexist_ok[0m[1;33m)[0m[1;33m[0m[1;33m[0m[0m
[0m[0;32m    216[0m         [1;32mexcept[0m [0mFileExistsError[0m[1;33m:[0m[1;33m[0m[1;33m[0m[0m
[0;32m    217[0m             [1;31m# Defeats race condition when another thread created the path[0m[1;33m[0m[1;33m[0m[0m

[1;32mC:\Anaconda\lib\os.py[0m in [0;36mmakedirs[1;34m(name, mode, exist_ok)[0m
[0;32m    213[0m     [1;32mif[0m [0mhead[0m [1;32mand[0m [0mtail[0m [1;32mand[0m [1;32mnot[0m [0mpath[0m[1;33m.[0m[0mexists[0m[1;33m([0m[0mhead[0m[1;33m)[0m[1;33m:[0m[1;33m[0m[1;33m[0m[0m
[0;32m    214[0m         [1;32mtry[0m[1;33m:[0m[1;33m[0m[1;33m[0m[0m
[1;32m--> 215[1;33m             [0mmakedirs[0m[1;33m([0m[0mhead[0m[1;33m,[0m [0mexist_ok[0m[1;33m=[0m[0mexist_ok[0m[1;33m)[0m[1;33m[0m[1;33m[0m[0m
[0m[0;32m    216[0m         [1;32mexcept[0m [0mFileExistsError[0m[1;33m:[0m[1;33m[0m[1;33m[0m[0m
[0;32m    217[0m             [1;31m# Defeats race condition when another thread created the path[0m[1;33m[0m[1;33m[0m[0m

[1;32mC:\Anaconda\lib\os.py[0m in [0;36mmakedirs[1;34m(name, mode, exist_ok)[0m
[0;32m    213[0m     [1;32mif[0m [0mhead[0m [1;32mand[0m [0mtail[0m [1;32mand[0m [1;32mnot[0m [0mpath[0m[1;33m.[0m[0mexists[0m[1;33m([0m[0mhead[0m[1;33m)[0m[1;33m:[0m[1;33m[0m[1;33m[0m[0m
[0;32m    214[0m         [1;32mtry[0m[1;33m:[0m[1;33m[0m[1;33m[0m[0m
[1;32m--> 215[1;33m             [0mmakedirs[0m[1;33m([0m[0mhead[0m[1;33m,[0m [0mexist_ok[0m[1;33m=[0m[0mexist_ok[0m[1;33m)[0m[1;33m[0m[1;33m[0m[0m
[0m[0;32m    216[0m         [1;32mexcept[0m [0mFileExistsError[0m[1;33m:[0m[1;33m[0m[1;33m[0m[0m
[0;32m    217[0m             [1;31m# Defeats race condition when another thread created the path[0m[1;33m[0m[1;33m[0m[0m

[1;32mC:\Anaconda\lib\os.py[0m in [0;36mmakedirs[1;34m(name, mode, exist_ok)[0m
[0;32m    223[0m             [1;32mreturn[0m[1;33m[0m[1;33m[0m[0m
[0;32m    224[0m     [1;32mtry[0m[1;33m:[0m[1;33m[0m[1;33m[0m[0m
[1;32m--> 225[1;33m         [0mmkdir[0m[1;33m([0m[0mname[0m[1;33m,[0m [0mmode[0m[1;33m)[0m[1;33m[0m[1;33m[0m[0m
[0m[0;32m    226[0m     [1;32mexcept[0m [0mOSError[0m[1;33m:[0m[1;33m[0m[1;33m[0m[0m
[0;32m    227[0m         [1;31m# Cannot rely on checking for EEXIST, since the operating system[0m[1;33m[0m[1;33m[0m[0m

[1;31mPermissionError[0m: [WinError 5] Acceso denegado: '..\\..\\_output'
PermissionError: [WinError 5] Acceso denegado: '..\\..\\_output'

