Traceback (most recent call last):
  File "C:\Anaconda\lib\site-packages\jupyter_cache\executors\utils.py", line 58, in single_nb_execution
    executenb(
  File "C:\Anaconda\lib\site-packages\nbclient\client.py", line 1204, in execute
    return NotebookClient(nb=nb, resources=resources, km=km, **kwargs).execute()
  File "C:\Anaconda\lib\site-packages\nbclient\util.py", line 84, in wrapped
    return just_run(coro(*args, **kwargs))
  File "C:\Anaconda\lib\site-packages\nbclient\util.py", line 62, in just_run
    return loop.run_until_complete(coro)
  File "C:\Anaconda\lib\asyncio\base_events.py", line 647, in run_until_complete
    return future.result()
  File "C:\Anaconda\lib\site-packages\nbclient\client.py", line 663, in async_execute
    await self.async_execute_cell(
  File "C:\Anaconda\lib\site-packages\nbclient\client.py", line 965, in async_execute_cell
    await self._check_raise_for_error(cell, cell_index, exec_reply)
  File "C:\Anaconda\lib\site-packages\nbclient\client.py", line 862, in _check_raise_for_error
    raise CellExecutionError.from_cell_and_msg(cell, exec_reply_content)
nbclient.exceptions.CellExecutionError: An error occurred while executing the following cell:
------------------
# Importing data
with open( r'../_data/data_endes.pickle', 'rb') as f:
    df = pickle.load(f )
------------------

[1;31m---------------------------------------------------------------------------[0m
[1;31mFileNotFoundError[0m                         Traceback (most recent call last)
[1;32m~\AppData\Local\Temp\ipykernel_17396\441731810.py[0m in [0;36m<module>[1;34m[0m
[0;32m      1[0m [1;31m# Importing data[0m[1;33m[0m[1;33m[0m[0m
[1;32m----> 2[1;33m [1;32mwith[0m [0mopen[0m[1;33m([0m [1;34mr'../_data/data_endes.pickle'[0m[1;33m,[0m [1;34m'rb'[0m[1;33m)[0m [1;32mas[0m [0mf[0m[1;33m:[0m[1;33m[0m[1;33m[0m[0m
[0m[0;32m      3[0m     [0mdf[0m [1;33m=[0m [0mpickle[0m[1;33m.[0m[0mload[0m[1;33m([0m[0mf[0m [1;33m)[0m[1;33m[0m[1;33m[0m[0m

[1;31mFileNotFoundError[0m: [Errno 2] No such file or directory: '../_data/data_endes.pickle'
FileNotFoundError: [Errno 2] No such file or directory: '../_data/data_endes.pickle'

