Traceback (most recent call last):
  File "C:\Anaconda\lib\site-packages\jupyter_cache\executors\utils.py", line 58, in single_nb_execution
    executenb(
  File "C:\Anaconda\lib\site-packages\nbclient\client.py", line 1204, in execute
    return NotebookClient(nb=nb, resources=resources, km=km, **kwargs).execute()
  File "C:\Anaconda\lib\site-packages\nbclient\util.py", line 84, in wrapped
    return just_run(coro(*args, **kwargs))
  File "C:\Anaconda\lib\site-packages\nbclient\util.py", line 62, in just_run
    return loop.run_until_complete(coro)
  File "C:\Anaconda\lib\asyncio\base_events.py", line 647, in run_until_complete
    return future.result()
  File "C:\Anaconda\lib\site-packages\nbclient\client.py", line 663, in async_execute
    await self.async_execute_cell(
  File "C:\Anaconda\lib\site-packages\nbclient\client.py", line 965, in async_execute_cell
    await self._check_raise_for_error(cell, cell_index, exec_reply)
  File "C:\Anaconda\lib\site-packages\nbclient\client.py", line 862, in _check_raise_for_error
    raise CellExecutionError.from_cell_and_msg(cell, exec_reply_content)
nbclient.exceptions.CellExecutionError: An error occurred while executing the following cell:
------------------
enaho = pd.read_stata(r"../_data/enaho.dta")
enaho
------------------

[1;31m---------------------------------------------------------------------------[0m
[1;31mFileNotFoundError[0m                         Traceback (most recent call last)
[1;32m~\AppData\Local\Temp\ipykernel_9032\968085571.py[0m in [0;36m<module>[1;34m[0m
[1;32m----> 1[1;33m [0menaho[0m [1;33m=[0m [0mpd[0m[1;33m.[0m[0mread_stata[0m[1;33m([0m[1;34mr"../_data/enaho.dta"[0m[1;33m)[0m[1;33m[0m[1;33m[0m[0m
[0m[0;32m      2[0m [0menaho[0m[1;33m[0m[1;33m[0m[0m

[1;32mC:\Anaconda\lib\site-packages\pandas\io\stata.py[0m in [0;36mread_stata[1;34m(filepath_or_buffer, convert_dates, convert_categoricals, index_col, convert_missing, preserve_dtypes, columns, order_categoricals, chunksize, iterator, compression, storage_options)[0m
[0;32m   2002[0m ) -> DataFrame | StataReader:
[0;32m   2003[0m [1;33m[0m[0m
[1;32m-> 2004[1;33m     reader = StataReader(
[0m[0;32m   2005[0m         [0mfilepath_or_buffer[0m[1;33m,[0m[1;33m[0m[1;33m[0m[0m
[0;32m   2006[0m         [0mconvert_dates[0m[1;33m=[0m[0mconvert_dates[0m[1;33m,[0m[1;33m[0m[1;33m[0m[0m

[1;32mC:\Anaconda\lib\site-packages\pandas\io\stata.py[0m in [0;36m__init__[1;34m(self, path_or_buf, convert_dates, convert_categoricals, index_col, convert_missing, preserve_dtypes, columns, order_categoricals, chunksize, compression, storage_options)[0m
[0;32m   1149[0m [1;33m[0m[0m
[0;32m   1150[0m         [0mself[0m[1;33m.[0m[0m_native_byteorder[0m [1;33m=[0m [0m_set_endianness[0m[1;33m([0m[0msys[0m[1;33m.[0m[0mbyteorder[0m[1;33m)[0m[1;33m[0m[1;33m[0m[0m
[1;32m-> 1151[1;33m         with get_handle(
[0m[0;32m   1152[0m             [0mpath_or_buf[0m[1;33m,[0m[1;33m[0m[1;33m[0m[0m
[0;32m   1153[0m             [1;34m"rb"[0m[1;33m,[0m[1;33m[0m[1;33m[0m[0m

[1;32mC:\Anaconda\lib\site-packages\pandas\io\common.py[0m in [0;36mget_handle[1;34m(path_or_buf, mode, encoding, compression, memory_map, is_text, errors, storage_options)[0m
[0;32m    793[0m         [1;32melse[0m[1;33m:[0m[1;33m[0m[1;33m[0m[0m
[0;32m    794[0m             [1;31m# Binary mode[0m[1;33m[0m[1;33m[0m[0m
[1;32m--> 795[1;33m             [0mhandle[0m [1;33m=[0m [0mopen[0m[1;33m([0m[0mhandle[0m[1;33m,[0m [0mioargs[0m[1;33m.[0m[0mmode[0m[1;33m)[0m[1;33m[0m[1;33m[0m[0m
[0m[0;32m    796[0m         [0mhandles[0m[1;33m.[0m[0mappend[0m[1;33m([0m[0mhandle[0m[1;33m)[0m[1;33m[0m[1;33m[0m[0m
[0;32m    797[0m [1;33m[0m[0m

[1;31mFileNotFoundError[0m: [Errno 2] No such file or directory: '../_data/enaho.dta'
FileNotFoundError: [Errno 2] No such file or directory: '../_data/enaho.dta'

